2022-04-21 13:31:05,824 INFO    MainThread:14374 [internal.py:wandb_internal():92] W&B internal server running at pid: 14374, started at: 2022-04-21 13:31:05.824261
2022-04-21 13:31:05,827 INFO    WriterThread:14374 [datastore.py:open_for_write():77] open: /com.docker.devenvironments.code/project/large_models/wandb/run-20220421_133105-23m9m455/run-23m9m455.wandb
2022-04-21 13:31:05,829 DEBUG   SenderThread:14374 [sender.py:send():235] send: header
2022-04-21 13:31:05,829 DEBUG   SenderThread:14374 [sender.py:send():235] send: run
2022-04-21 13:31:35,211 DEBUG   HandlerThread:14374 [handler.py:handle_request():141] handle_request: shutdown
2022-04-21 13:31:35,213 INFO    HandlerThread:14374 [handler.py:finish():778] shutting down handler
2022-04-21 13:31:35,850 INFO    WriterThread:14374 [datastore.py:close():281] close: /com.docker.devenvironments.code/project/large_models/wandb/run-20220421_133105-23m9m455/run-23m9m455.wandb
2022-04-21 13:31:39,402 ERROR   SenderThread:14374 [retry.py:__call__():126] Retry attempt failed:
Traceback (most recent call last):
  File "/usr/lib/python3/dist-packages/urllib3/connectionpool.py", line 421, in _make_request
    six.raise_from(e, None)
  File "<string>", line 3, in raise_from
  File "/usr/lib/python3/dist-packages/urllib3/connectionpool.py", line 416, in _make_request
    httplib_response = conn.getresponse()
  File "/usr/lib/python3.8/http/client.py", line 1348, in getresponse
    response.begin()
  File "/usr/lib/python3.8/http/client.py", line 316, in begin
    version, status, reason = self._read_status()
  File "/usr/lib/python3.8/http/client.py", line 277, in _read_status
    line = str(self.fp.readline(_MAXLINE + 1), "iso-8859-1")
  File "/usr/lib/python3.8/socket.py", line 669, in readinto
    return self._sock.recv_into(b)
  File "/usr/lib/python3.8/ssl.py", line 1241, in recv_into
    return self.read(nbytes, buffer)
  File "/usr/lib/python3.8/ssl.py", line 1099, in read
    return self._sslobj.read(len, buffer)
socket.timeout: The read operation timed out

During handling of the above exception, another exception occurred:

Traceback (most recent call last):
  File "/usr/lib/python3/dist-packages/requests/adapters.py", line 439, in send
    resp = conn.urlopen(
  File "/usr/lib/python3/dist-packages/urllib3/connectionpool.py", line 719, in urlopen
    retries = retries.increment(
  File "/usr/lib/python3/dist-packages/urllib3/util/retry.py", line 400, in increment
    raise six.reraise(type(error), error, _stacktrace)
  File "/usr/lib/python3/dist-packages/six.py", line 703, in reraise
    raise value
  File "/usr/lib/python3/dist-packages/urllib3/connectionpool.py", line 665, in urlopen
    httplib_response = self._make_request(
  File "/usr/lib/python3/dist-packages/urllib3/connectionpool.py", line 423, in _make_request
    self._raise_timeout(err=e, url=url, timeout_value=read_timeout)
  File "/usr/lib/python3/dist-packages/urllib3/connectionpool.py", line 330, in _raise_timeout
    raise ReadTimeoutError(
urllib3.exceptions.ReadTimeoutError: HTTPSConnectionPool(host='api.wandb.ai', port=443): Read timed out. (read timeout=10)

During handling of the above exception, another exception occurred:

Traceback (most recent call last):
  File "/usr/local/lib/python3.8/dist-packages/wandb/sdk/lib/retry.py", line 102, in __call__
    result = self._call_fn(*args, **kwargs)
  File "/usr/local/lib/python3.8/dist-packages/wandb/sdk/internal/internal_api.py", line 140, in execute
    return self.client.execute(*args, **kwargs)
  File "/usr/local/lib/python3.8/dist-packages/wandb/vendor/gql-0.2.0/wandb_gql/client.py", line 52, in execute
    result = self._get_result(document, *args, **kwargs)
  File "/usr/local/lib/python3.8/dist-packages/wandb/vendor/gql-0.2.0/wandb_gql/client.py", line 60, in _get_result
    return self.transport.execute(document, *args, **kwargs)
  File "/usr/local/lib/python3.8/dist-packages/wandb/vendor/gql-0.2.0/wandb_gql/transport/requests.py", line 38, in execute
    request = requests.post(self.url, **post_args)
  File "/usr/lib/python3/dist-packages/requests/api.py", line 116, in post
    return request('post', url, data=data, json=json, **kwargs)
  File "/usr/lib/python3/dist-packages/requests/api.py", line 60, in request
    return session.request(method=method, url=url, **kwargs)
  File "/usr/lib/python3/dist-packages/requests/sessions.py", line 533, in request
    resp = self.send(prep, **send_kwargs)
  File "/usr/lib/python3/dist-packages/requests/sessions.py", line 646, in send
    r = adapter.send(request, **kwargs)
  File "/usr/lib/python3/dist-packages/requests/adapters.py", line 529, in send
    raise ReadTimeout(e, request=request)
requests.exceptions.ReadTimeout: HTTPSConnectionPool(host='api.wandb.ai', port=443): Read timed out. (read timeout=10)
2022-04-21 13:33:13,405 INFO    SenderThread:14374 [dir_watcher.py:__init__():169] watching files in: /com.docker.devenvironments.code/project/large_models/wandb/run-20220421_133105-23m9m455/files
2022-04-21 13:33:13,405 INFO    SenderThread:14374 [sender.py:_start_run_threads():812] run started: 23m9m455 with start time 1650547865
2022-04-21 13:33:13,406 INFO    SenderThread:14374 [sender.py:finish():1078] shutting down sender
2022-04-21 13:33:13,407 INFO    SenderThread:14374 [dir_watcher.py:finish():283] shutting down directory watcher
2022-04-21 13:33:14,407 INFO    SenderThread:14374 [dir_watcher.py:finish():313] scan: /com.docker.devenvironments.code/project/large_models/wandb/run-20220421_133105-23m9m455/files
2022-04-21 13:33:14,408 INFO    SenderThread:14374 [dir_watcher.py:finish():327] scan save: /com.docker.devenvironments.code/project/large_models/wandb/run-20220421_133105-23m9m455/files/config.yaml config.yaml
2022-04-21 13:33:14,409 INFO    SenderThread:14374 [file_pusher.py:finish():145] shutting down file pusher
2022-04-21 13:33:14,410 INFO    SenderThread:14374 [file_pusher.py:join():150] waiting for file pusher
2022-04-21 13:33:15,290 INFO    Thread-9  :14374 [upload_job.py:push():137] Uploaded file /com.docker.devenvironments.code/project/large_models/wandb/run-20220421_133105-23m9m455/files/config.yaml
2022-04-21 13:33:16,357 INFO    MainThread:14374 [internal.py:handle_exit():82] Internal process exited
