2022-04-06 12:47:39,753 INFO    MainThread:17961 [wandb_setup.py:_flush():75] Loading settings from /home/vscode/.config/wandb/settings
2022-04-06 12:47:39,754 INFO    MainThread:17961 [wandb_setup.py:_flush():75] Loading settings from /com.docker.devenvironments.code/project/large_models/wandb/settings
2022-04-06 12:47:39,754 INFO    MainThread:17961 [wandb_setup.py:_flush():75] Loading settings from environment variables: {}
2022-04-06 12:47:39,754 INFO    MainThread:17961 [wandb_setup.py:_flush():75] Inferring run settings from compute environment: {'program_relpath': 'project/large_models/RunTest.py', 'program': 'RunTest.py'}
2022-04-06 12:47:39,754 INFO    MainThread:17961 [wandb_init.py:_log_setup():405] Logging user logs to /com.docker.devenvironments.code/project/large_models/wandb/run-20220406_124739-p71v4b58/logs/debug.log
2022-04-06 12:47:39,755 INFO    MainThread:17961 [wandb_init.py:_log_setup():406] Logging internal logs to /com.docker.devenvironments.code/project/large_models/wandb/run-20220406_124739-p71v4b58/logs/debug-internal.log
2022-04-06 12:47:39,756 INFO    MainThread:17961 [wandb_init.py:init():439] calling init triggers
2022-04-06 12:47:39,756 INFO    MainThread:17961 [wandb_init.py:init():442] wandb.init called with sweep_config: {}
config: {'epochs': 30, 'learning_rate': 0.01, 'batch_size': 32, 'scoring_func': 'naive_grads', 'pacing_func': 'naive_linear_high_first', 'dataset': 'mnist', 'lam_zero': 0.1, 'lam_pace': 0.9}
2022-04-06 12:47:39,756 INFO    MainThread:17961 [wandb_init.py:init():492] starting backend
2022-04-06 12:47:39,757 INFO    MainThread:17961 [backend.py:_multiprocessing_setup():99] multiprocessing start_methods=fork,spawn,forkserver, using: spawn
2022-04-06 12:47:39,777 INFO    MainThread:17961 [backend.py:ensure_launched():219] starting backend process...
2022-04-06 12:47:39,785 INFO    MainThread:17961 [backend.py:ensure_launched():224] started backend process with pid: 18027
2022-04-06 12:47:39,788 INFO    MainThread:17961 [wandb_init.py:init():501] backend started and connected
2022-04-06 12:47:39,801 INFO    MainThread:17961 [wandb_init.py:init():565] updated telemetry
2022-04-06 12:47:39,818 INFO    MainThread:17961 [wandb_init.py:init():596] communicating run to backend with 30 second timeout
2022-04-06 12:47:40,733 INFO    MainThread:17961 [wandb_run.py:_on_init():1759] communicating current version
2022-04-06 12:47:40,852 INFO    MainThread:17961 [wandb_run.py:_on_init():1763] got version response upgrade_message: "wandb version 0.12.12 is available!  To upgrade, please run:\n $ pip install wandb --upgrade"

2022-04-06 12:47:40,852 INFO    MainThread:17961 [wandb_init.py:init():625] starting run threads in backend
2022-04-06 12:47:42,636 INFO    MainThread:17961 [wandb_run.py:_console_start():1733] atexit reg
2022-04-06 12:47:42,637 INFO    MainThread:17961 [wandb_run.py:_redirect():1606] redirect: SettingsConsole.REDIRECT
2022-04-06 12:47:42,638 INFO    MainThread:17961 [wandb_run.py:_redirect():1611] Redirecting console.
2022-04-06 12:47:42,646 INFO    MainThread:17961 [wandb_run.py:_redirect():1667] Redirects installed.
2022-04-06 12:47:42,646 INFO    MainThread:17961 [wandb_init.py:init():664] run started, returning control to user process
2022-04-06 12:51:11,331 INFO    MainThread:17961 [wandb_run.py:_atexit_cleanup():1702] got exitcode: 255
2022-04-06 12:51:11,333 INFO    MainThread:17961 [wandb_run.py:_restore():1674] restore
2022-04-06 12:51:13,621 INFO    MainThread:17961 [wandb_run.py:_restore():1674] restore
2022-04-06 12:51:16,780 ERROR   MainThread:17961 [wandb_run.py:_atexit_cleanup():1723] Problem finishing run
Traceback (most recent call last):
  File "/usr/local/lib/python3.8/dist-packages/wandb/sdk/wandb_run.py", line 1711, in _atexit_cleanup
    self._on_finish()
  File "/usr/local/lib/python3.8/dist-packages/wandb/sdk/wandb_run.py", line 1811, in _on_finish
    self._console_stop()  # TODO: there's a race here with jupyter console logging
  File "/usr/local/lib/python3.8/dist-packages/wandb/sdk/wandb_run.py", line 1751, in _console_stop
    self._restore()
  File "/usr/local/lib/python3.8/dist-packages/wandb/sdk/wandb_run.py", line 1680, in _restore
    self._err_redir.uninstall()
  File "/usr/local/lib/python3.8/dist-packages/wandb/sdk/lib/redirect.py", line 747, in uninstall
    self._emulator_write_thread.join(timeout=5)
  File "/usr/lib/python3.8/threading.py", line 1015, in join
    self._wait_for_tstate_lock(timeout=max(timeout, 0))
  File "/usr/lib/python3.8/threading.py", line 1027, in _wait_for_tstate_lock
    elif lock.acquire(block, timeout):
  File "/usr/local/lib/python3.8/dist-packages/wandb/sdk/lib/redirect.py", line 649, in handler
    self.handle_window_size_change()
  File "/usr/local/lib/python3.8/dist-packages/wandb/sdk/lib/redirect.py", line 680, in handle_window_size_change
    fcntl.ioctl(fd, termios.TIOCSWINSZ, win_size)
OSError: [Errno 9] Bad file descriptor
