
INIT: Using found mnist data
INIT: Finished creating train dataset
   label  score
i
0      2    NaN
1      0    NaN
2      4    NaN
3      8    NaN
6      0    NaN
MAIN: Started Training
Number of batches to use:  1750
Batch =0
2022-04-07 12:24:02.509225: E tensorflow/stream_executor/cuda/cuda_driver.cc:271] failed call to cuInit: UNKNOWN ERROR (34)
2022-04-07 12:24:02.509344: I tensorflow/stream_executor/cuda/cuda_diagnostics.cc:156] kernel driver does not appear to be running on this host (e175316c4453): /proc/driver/nvidia/version does not exist
2022-04-07 12:24:02.510150: I tensorflow/core/platform/cpu_feature_guard.cc:151] This TensorFlow binary is optimized with oneAPI Deep Neural Network Library (oneDNN) to use the following CPU instructions in performance-critical operations:  AVX2 FMA
To enable them in other operations, rebuild TensorFlow with the appropriate compiler flags.
Batch =500
Batch =1000
Batch =1500
used 0 epoch
pacing dataused  5599
       label  score          0
i
62848      2    0.0   0.000001
65660      0    1.0   0.000002
57494      0    2.0   0.000004
40086      0    3.0   0.000004
52691      0    4.0   0.000006
...      ...    ...        ...
31745      7    NaN   9.890978
51210      9    NaN   10.24667
14585      5    NaN   10.32769
41103      4    NaN  11.405199
43515      3    NaN   13.43767
[55994 rows x 3 columns]
[1414, 123, 1091, 568, 408, 155, 740, 942, 154, 4]
Number of batches to use:  438
/usr/local/lib/python3.8/dist-packages/pandas/core/indexes/base.py:6982: FutureWarning: In a future version, the Index constructor will not infer numeric dtypes when passed object-dtype sequences (matching Series behavior)
  return Index(sequences[0], name=names)
Traceback (most recent call last):
  File "RunTest.py", line 214, in <module>
    main(args)
  File "RunTest.py", line 182, in main
    cla['Loss-Avg-'+keys[i]] = class_loss_avg[i]
IndexError: list index out of range