INIT: Using found mnist data
INIT: Finished creating train dataset
   label  score
i
0      2    NaN
1      0    NaN
2      4    NaN
3      8    NaN
6      0    NaN
MAIN: Started Training
Batch =0
2022-04-05 11:01:59.877633: E tensorflow/stream_executor/cuda/cuda_driver.cc:271] failed call to cuInit: UNKNOWN ERROR (34)
2022-04-05 11:01:59.877703: I tensorflow/stream_executor/cuda/cuda_diagnostics.cc:156] kernel driver does not appear to be running on this host (69dc0e526fe3): /proc/driver/nvidia/version does not exist
2022-04-05 11:01:59.877936: I tensorflow/core/platform/cpu_feature_guard.cc:151] This TensorFlow binary is optimized with oneAPI Deep Neural Network Library (oneDNN) to use the following CPU instructions in performance-critical operations:  AVX2 FMA
To enable them in other operations, rebuild TensorFlow with the appropriate compiler flags.
Batch =100
Batch =200
Batch =300
Batch =400
Batch =500
Batch =600
Batch =700
Batch =800
Batch =900
Batch =1000
Batch =1100
Batch =1200
Batch =1300
Batch =1400
Batch =1500
Batch =1600
Batch =1700
   label  score         0
i
0      2    NaN  0.041181
1      0    NaN  0.008421
2      4    NaN  1.886471
3      8    NaN  0.339532
6      0    NaN  0.002765
None
   label score         0
i
0      2  None  0.041181
1      0  None  0.008421
2      4  None  1.886471
3      8  None  0.339532
6      0  None  0.002765
   label  score         0
i
0      2    0.0  0.041181
1      0    1.0  0.008421
2      4    2.0  1.886471
3      8    3.0  0.339532
6      0    4.0  0.002765
/usr/local/lib/python3.8/dist-packages/pandas/core/indexes/base.py:6982: FutureWarning: In a future version, the Index constructor will not infer numeric dtypes when passed object-dtype sequences (matching Series behavior)
  return Index(sequences[0], name=names)
Traceback (most recent call last):
  File "/usr/local/lib/python3.8/dist-packages/pandas/core/indexes/base.py", line 3621, in get_loc
    return self._engine.get_loc(casted_key)
  File "pandas/_libs/index.pyx", line 136, in pandas._libs.index.IndexEngine.get_loc
  File "pandas/_libs/index.pyx", line 163, in pandas._libs.index.IndexEngine.get_loc
  File "pandas/_libs/hashtable_class_helper.pxi", line 5198, in pandas._libs.hashtable.PyObjectHashTable.get_item
  File "pandas/_libs/hashtable_class_helper.pxi", line 5206, in pandas._libs.hashtable.PyObjectHashTable.get_item
KeyError: 'use'
The above exception was the direct cause of the following exception:
Traceback (most recent call last):
  File "/usr/local/lib/python3.8/dist-packages/pandas/core/frame.py", line 3799, in _set_item_mgr
    loc = self._info_axis.get_loc(key)
  File "/usr/local/lib/python3.8/dist-packages/pandas/core/indexes/base.py", line 3623, in get_loc
    raise KeyError(key) from err
KeyError: 'use'
During handling of the above exception, another exception occurred:
Traceback (most recent call last):
  File "RunTest.py", line 183, in <module>
    main(args)
  File "RunTest.py", line 145, in main
    train_data_gen.on_epoch_end(df_train_losses)
  File "/com.docker.devenvironments.code/project/large_models/datagen.py", line 31, in on_epoch_end
    self.df['use'] = use
  File "/usr/local/lib/python3.8/dist-packages/pandas/core/frame.py", line 3645, in __setitem__
    self._set_item_frame_value(key, value)
  File "/usr/local/lib/python3.8/dist-packages/pandas/core/frame.py", line 3788, in _set_item_frame_value
    self._set_item_mgr(key, arraylike)
  File "/usr/local/lib/python3.8/dist-packages/pandas/core/frame.py", line 3802, in _set_item_mgr
    self._mgr.insert(len(self._info_axis), key, value)
  File "/usr/local/lib/python3.8/dist-packages/pandas/core/internals/managers.py", line 1235, in insert
    raise ValueError(
ValueError: Expected a 1D array, got an array with shape (55994, 3)