
INIT: Using found mnist data
                                                     img  label      i   test
0      [  0   0   0   0   0   0   0   0   0   0   0  ...      2      0  False
1      [  0   0   0   0   0   0   0   0   0   0   0  ...      0      1  False
2      [  0   0   0   0   0   0   0   0   0   0   0  ...      4      2  False
3      [  0   0   0   0   0   0   0   0   0   0   0  ...      8      3  False
6      [  0   0   0   0   0   0   0   0   0   0   0  ...      0      6  False
...                                                  ...    ...    ...    ...
69995  [  0   0   0   0   0   0   0   0   0   0   0  ...      7  69995  False
69996  [  0   0   0   0   0   0   0   0   0   0   0  ...      1  69996  False
69997  [  0   0   0   0   0   0   0   0   0   0   0  ...      6  69997  False
69998  [  0   0   0   0   0   0   0   0   0   0   0  ...      1  69998  False
69999  [  0   0   0   0   0   0   0   0   0   0   0  ...      5  69999  False
[55994 rows x 4 columns]
2022-03-31 13:00:01.126533: E tensorflow/stream_executor/cuda/cuda_driver.cc:271] failed call to cuInit: UNKNOWN ERROR (34)
2022-03-31 13:00:01.128082: I tensorflow/stream_executor/cuda/cuda_diagnostics.cc:156] kernel driver does not appear to be running on this host (b371895a6098): /proc/driver/nvidia/version does not exist
2022-03-31 13:00:01.133197: I tensorflow/core/platform/cpu_feature_guard.cc:151] This TensorFlow binary is optimized with oneAPI Deep Neural Network Library (oneDNN) to use the following CPU instructions in performance-critical operations:  AVX2 FMA
To enable them in other operations, rebuild TensorFlow with the appropriate compiler flags.
2022-03-31 13:00:01.148811: W tensorflow/core/framework/cpu_allocator_impl.cc:82] Allocation of 351194368 exceeds 10% of free system memory.
2022-03-31 13:01:14.083976: W tensorflow/core/framework/cpu_allocator_impl.cc:82] Allocation of 175597184 exceeds 10% of free system memory.
INIT: Finished creating train dataset
INIT: Finished creating test dataset
Setup Complete, Starting training:
2022-03-31 13:01:27.470332: W tensorflow/core/framework/cpu_allocator_impl.cc:82] Allocation of 87845632 exceeds 10% of free system memory.
Traceback (most recent call last):
  File "/usr/local/lib/python3.8/dist-packages/pandas/core/indexes/base.py", line 3621, in get_loc
    return self._engine.get_loc(casted_key)
  File "pandas/_libs/index.pyx", line 136, in pandas._libs.index.IndexEngine.get_loc
  File "pandas/_libs/index.pyx", line 163, in pandas._libs.index.IndexEngine.get_loc
  File "pandas/_libs/hashtable_class_helper.pxi", line 5198, in pandas._libs.hashtable.PyObjectHashTable.get_item
  File "pandas/_libs/hashtable_class_helper.pxi", line 5206, in pandas._libs.hashtable.PyObjectHashTable.get_item
KeyError: 'img'
The above exception was the direct cause of the following exception:
Traceback (most recent call last):
  File "RunTest.py", line 165, in <module>
    main(args)
  File "RunTest.py", line 105, in main
    train_ds = sf.collect_train_data(df_train_losses,info)
  File "/com.docker.devenvironments.code/project/large_models/supporting_functions.py", line 150, in collect_train_data
    img_dim_shift(df['img'].values),
  File "/usr/local/lib/python3.8/dist-packages/pandas/core/frame.py", line 3505, in __getitem__
    indexer = self.columns.get_loc(key)
  File "/usr/local/lib/python3.8/dist-packages/pandas/core/indexes/base.py", line 3623, in get_loc
    raise KeyError(key) from err
KeyError: 'img'